<sdf version='1.7'>
  <world name='default'>
    <light name='sun' type='directional'>
      <cast_shadows>0</cast_shadows>
      <pose>0 0 10 0 -0 0</pose>
      <diffuse>1 1 1 1</diffuse>
      <specular>0.9 0.9 0.9 1</specular>
      <attenuation>
        <range>1000</range>
        <constant>0.9</constant>
        <linear>0.01</linear>
        <quadratic>0.001</quadratic>
      </attenuation>
      <direction>-0.5 0.1 -0.9</direction>
      <spot>
        <inner_angle>0</inner_angle>
        <outer_angle>0</outer_angle>
        <falloff>0</falloff>
      </spot>
    </light>
    <model name='ground_plane'>
      <static>1</static>
      <link name='link'>
        <collision name='collision'>
          <geometry>
            <plane>
              <normal>0 0 1</normal>
              <size>100 100</size>
            </plane>
          </geometry>
          <surface>
            <friction>
              <ode>
                <mu>100</mu>
                <mu2>50</mu2>
              </ode>
              <torsional>
                <ode/>
              </torsional>
            </friction>
            <contact>
              <ode/>
            </contact>
            <bounce/>
          </surface>
          <max_contacts>10</max_contacts>
        </collision>
        <visual name='visual'>
          <cast_shadows>0</cast_shadows>
          <geometry>
            <plane>
              <normal>0 0 1</normal>
              <size>100 100</size>
            </plane>
          </geometry>
          <material>
            <script>
              <uri>file://media/materials/scripts/gazebo.material</uri>
              <name>Gazebo/Grey</name>
            </script>
          </material>
        </visual>
        <self_collide>0</self_collide>
        <enable_wind>0</enable_wind>
        <kinematic>0</kinematic>
      </link>
    </model>
    <gravity>0 0 -9.8</gravity>
    <magnetic_field>6e-06 2.3e-05 -4.2e-05</magnetic_field>
    <atmosphere type='adiabatic'/>
    <physics type='ode'>
      <max_step_size>0.001</max_step_size>
      <real_time_factor>1</real_time_factor>
      <real_time_update_rate>1000</real_time_update_rate>
    </physics>
    <scene>
      <ambient>0.4 0.4 0.4 1</ambient>
      <background>1 1 1 1</background>
      <shadows>1</shadows>
    </scene>
    <wind/>
    <spherical_coordinates>
      <surface_model>EARTH_WGS84</surface_model>
      <latitude_deg>0</latitude_deg>
      <longitude_deg>0</longitude_deg>
      <elevation>0</elevation>
      <heading_deg>0</heading_deg>
    </spherical_coordinates>
    <model name='track_1'>
      <link name='link_0'>
        <inertial>
          <mass>1</mass>
          <inertia>
            <ixx>0.166667</ixx>
            <ixy>0</ixy>
            <ixz>0</ixz>
            <iyy>0.166667</iyy>
            <iyz>0</iyz>
            <izz>0.166667</izz>
          </inertia>
          <pose>0 0 0 0 -0 0</pose>
        </inertial>
        <pose>-0 -0 6e-06 0 -0 0</pose>
        <gravity>1</gravity>
        <self_collide>0</self_collide>
        <kinematic>0</kinematic>
        <enable_wind>0</enable_wind>
        <visual name='visual'>
          <pose>0 0 -0.03 0 -0 0</pose>
          <geometry>
            <box>
              <size>12 10.4 0.05</size>
            </box>
          </geometry>
          <material>
            <lighting>1</lighting>
            <script>
              <uri>model://warehouse_rover_ros2/urdf/track_1/materials/scripts</uri>
              <uri>model://warehouse_rover_ros2/urdf/track_1/materials/textures</uri>
              <name>track_1/Diffuse</name>
            </script>
            <shader type='pixel'>
              <normal_map>__default__</normal_map>
            </shader>
            <ambient>0.3 0.3 0.3 1</ambient>
            <diffuse>0.7 0.7 0.7 1</diffuse>
            <specular>0.01 0.01 0.01 1</specular>
            <emissive>0 0 0 1</emissive>
          </material>
          <transparency>0</transparency>
          <cast_shadows>1</cast_shadows>
        </visual>
        <collision name='collision'>
          <laser_retro>0</laser_retro>
          <max_contacts>10</max_contacts>
          <pose>0 0 0 0 -0 0</pose>
          <geometry>
            <box>
              <size>12 10.4 0.05</size>
            </box>
          </geometry>
          <surface>
            <friction>
              <ode>
                <mu>1</mu>
                <mu2>1</mu2>
                <fdir1>0 0 0</fdir1>
                <slip1>0</slip1>
                <slip2>0</slip2>
              </ode>
              <torsional>
                <coefficient>1</coefficient>
                <patch_radius>0</patch_radius>
                <surface_radius>0</surface_radius>
                <use_patch_radius>1</use_patch_radius>
                <ode>
                  <slip>0</slip>
                </ode>
              </torsional>
            </friction>
            <bounce>
              <restitution_coefficient>0</restitution_coefficient>
              <threshold>1e+06</threshold>
            </bounce>
            <contact>
              <collide_without_contact>0</collide_without_contact>
              <collide_without_contact_bitmask>1</collide_without_contact_bitmask>
              <collide_bitmask>1</collide_bitmask>
              <ode>
                <soft_cfm>0</soft_cfm>
                <soft_erp>0.2</soft_erp>
                <kp>1e+13</kp>
                <kd>1</kd>
                <max_vel>0.01</max_vel>
                <min_depth>0</min_depth>
              </ode>
              <bullet>
                <split_impulse>1</split_impulse>
                <split_impulse_penetration_threshold>-0.01</split_impulse_penetration_threshold>
                <soft_cfm>0</soft_cfm>
                <soft_erp>0.2</soft_erp>
                <kp>1e+13</kp>
                <kd>1</kd>
              </bullet>
            </contact>
          </surface>
        </collision>
      </link>
      <static>1</static>
      <allow_auto_disable>1</allow_auto_disable>
      <pose>-1.31893 -0.619139 0 0 -0 0</pose>
    </model>
    <state world_name='default'>
      <sim_time>743 696000000</sim_time>
      <real_time>64 749396630</real_time>
      <wall_time>1731589133 98075184</wall_time>
      <iterations>64650</iterations>
      <model name='ground_plane'>
        <pose>0 0 0 0 -0 0</pose>
        <scale>1 1 1</scale>
        <link name='link'>
          <pose>0 0 0 0 -0 0</pose>
          <velocity>0 0 0 0 -0 0</velocity>
          <acceleration>0 0 0 0 -0 0</acceleration>
          <wrench>0 0 0 0 -0 0</wrench>
        </link>
      </model>
      <model name='rover_proto_A1_rviz'>
        <pose>3.3899 1.42774 0.194936 -1.4e-05 1.6e-05 -0.269276</pose>
        <scale>1 1 1</scale>
        <link name='Chassis'>
          <pose>3.3899 1.42774 0.194936 -1.4e-05 1.6e-05 -0.269276</pose>
          <velocity>0 -0 0 0 -0 0</velocity>
          <acceleration>-0 0 -0 5e-06 -1e-06 0</acceleration>
          <wrench>-0 0 -0 0 -0 0</wrench>
        </link>
        <link name='Wheel_1_Link'>
          <pose>3.66886 1.12771 0.154934 1.57081 -0.393163 -0.26928</pose>
          <velocity>0 -0 0 0 4e-06 0</velocity>
          <acceleration>-0 0 -0 -8.9e-05 -0.000322 0</acceleration>
          <wrench>-0 0 -0 0 -0 0</wrench>
        </link>
        <link name='Wheel_2_Link'>
          <pose>3.78325 1.54222 0.154928 1.57075 0.623828 -0.269303</pose>
          <velocity>0 -0 -0 2e-06 4e-06 -0</velocity>
          <acceleration>-0 0 0 -0.0001 -0.000362 -0</acceleration>
          <wrench>-0 0 0 0 -0 0</wrench>
        </link>
        <link name='Wheel_3_Link'>
          <pose>3.10847 1.72843 0.154939 1.57076 -0.62049 -0.269256</pose>
          <velocity>0 -0 0 3e-06 4e-06 -0</velocity>
          <acceleration>-0 0 -0 -0.000102 -0.00037 0</acceleration>
          <wrench>-0 0 -0 0 -0 0</wrench>
        </link>
        <link name='Wheel_4_Link'>
          <pose>2.99408 1.31394 0.154945 1.57081 -0.289623 -0.269281</pose>
          <velocity>0 -0 -0 1e-06 4e-06 0</velocity>
          <acceleration>-0 0 0 -8.9e-05 -0.000323 0</acceleration>
          <wrench>-0 0 0 0 -0 0</wrench>
        </link>
      </model>
      <model name='track_1'>
        <pose>2.59865 -1.95957 0.049994 0 0 -0.004983</pose>
        <scale>1 1 1</scale>
        <link name='link_0'>
          <pose>2.59865 -1.95957 0.05 0 0 -0.004983</pose>
          <velocity>0 0 0 0 -0 0</velocity>
          <acceleration>0 0 0 0 -0 0</acceleration>
          <wrench>0 0 0 0 -0 0</wrench>
        </link>
      </model>
      <light name='sun'>
        <pose>0 0 10 0 -0 0</pose>
      </light>
      <light name='user_directional_light_0'>
        <pose>3.28777 -7.89594 1 0 -0 0</pose>
      </light>
      <light name='user_directional_light_1'>
        <pose>-2.70099 1.56133 1 0 -0 0</pose>
      </light>
      <light name='user_directional_light_2'>
        <pose>5.65592 4.53366 1 0 -0 0</pose>
      </light>
      <light name='user_directional_light_3'>
        <pose>7.02737 -2.79913 1 0 -0 0</pose>
      </light>
      <light name='user_directional_light_4'>
        <pose>-2.73559 -5.19311 1 0 -0 0</pose>
      </light>
      <light name='user_directional_light_5'>
        <pose>10.6409 -2.37644 1 0 -0 0</pose>
      </light>
    </state>
    <gui fullscreen='0'>
      <camera name='user_camera'>
        <pose>-1.18622 2.30599 3.95059 0 0.823643 -0.291778</pose>
        <view_controller>orbit</view_controller>
        <projection_type>perspective</projection_type>
      </camera>
    </gui>
    <audio>
      <device>default</device>
    </audio>
    <model name='rover_proto_A1_rviz'>
      <link name='Chassis'>
        <inertial>
          <pose>-0.003619 -4e-06 -0.025334 0 -0 0</pose>
          <mass>18.0919</mass>
          <inertia>
            <ixx>0.190571</ixx>
            <ixy>-3.70553e-06</ixy>
            <ixz>0.00402853</ixz>
            <iyy>1.55584</iyy>
            <iyz>-8.33152e-06</iyz>
            <izz>1.731</izz>
          </inertia>
        </inertial>
        <collision name='Chassis_collision'>
          <pose>0 0 0 0 -0 0</pose>
          <geometry>
            <mesh>
              <scale>1 1 1</scale>
              <uri>model://warehouse_rover_ros2/urdf/rover_proto_A1/meshes/Chassis.STL</uri>
            </mesh>
          </geometry>
          <max_contacts>10</max_contacts>
          <surface>
            <contact>
              <ode/>
            </contact>
            <bounce/>
            <friction>
              <torsional>
                <ode/>
              </torsional>
              <ode/>
            </friction>
          </surface>
        </collision>
        <collision name='Chassis_fixed_joint_lump__Camera_Back_Link_collision_1'>
          <pose>-0.50128 0 0.046965 0 -0 0</pose>
          <geometry>
            <mesh>
              <scale>1 1 1</scale>
              <uri>model://warehouse_rover_ros2/urdf/rover_proto_A1/meshes/Camera_Back_Link.STL</uri>
            </mesh>
          </geometry>
          <max_contacts>10</max_contacts>
          <surface>
            <contact>
              <ode/>
            </contact>
            <bounce/>
            <friction>
              <torsional>
                <ode/>
              </torsional>
              <ode/>
            </friction>
          </surface>
        </collision>
        <collision name='Chassis_fixed_joint_lump__Camera_Fwd_Link_collision_2'>
          <pose>0.49872 0 0.046965 0 -0 0</pose>
          <geometry>
            <mesh>
              <scale>1 1 1</scale>
              <uri>model://warehouse_rover_ros2/urdf/rover_proto_A1/meshes/Camera_Fwd_Link.STL</uri>
            </mesh>
          </geometry>
          <surface>
            <contact>
              <ode/>
            </contact>
            <friction>
              <ode/>
              <torsional>
                <ode/>
              </torsional>
            </friction>
            <bounce/>
          </surface>
          <max_contacts>10</max_contacts>
        </collision>
        <collision name='Chassis_fixed_joint_lump__Lidar_Back_Link_collision_3'>
          <pose>-0.34128 0 0.166 0 -0 1.57</pose>
          <geometry>
            <mesh>
              <scale>1 1 1</scale>
              <uri>model://warehouse_rover_ros2/urdf/rover_proto_A1/meshes/Lidar_Back_Link.STL</uri>
            </mesh>
          </geometry>
          <surface>
            <contact>
              <ode/>
            </contact>
            <friction>
              <ode/>
              <torsional>
                <ode/>
              </torsional>
            </friction>
            <bounce/>
          </surface>
          <max_contacts>10</max_contacts>
        </collision>
        <collision name='Chassis_fixed_joint_lump__Lidar_Fwd_Link_collision_4'>
          <pose>0.33872 0 0.116 0 0 -1.57</pose>
          <geometry>
            <mesh>
              <scale>1 1 1</scale>
              <uri>model://warehouse_rover_ros2/urdf/rover_proto_A1/meshes/Lidar_Fwd_Link.STL</uri>
            </mesh>
          </geometry>
          <surface>
            <contact>
              <ode/>
            </contact>
            <friction>
              <ode/>
              <torsional>
                <ode/>
              </torsional>
            </friction>
            <bounce/>
          </surface>
          <max_contacts>10</max_contacts>
        </collision>
        <collision name='Chassis_fixed_joint_lump__Lights_Back_Link_collision_5'>
          <pose>0 0 0 0 -0 0</pose>
          <geometry>
            <mesh>
              <scale>1 1 1</scale>
              <uri>model://warehouse_rover_ros2/urdf/rover_proto_A1/meshes/Lights_Back_Link.STL</uri>
            </mesh>
          </geometry>
          <max_contacts>10</max_contacts>
          <surface>
            <contact>
              <ode/>
            </contact>
            <bounce/>
            <friction>
              <torsional>
                <ode/>
              </torsional>
              <ode/>
            </friction>
          </surface>
        </collision>
        <collision name='Chassis_fixed_joint_lump__Lights_Fwd_Link_collision_6'>
          <pose>0 0 0 0 -0 0</pose>
          <geometry>
            <mesh>
              <scale>1 1 1</scale>
              <uri>model://warehouse_rover_ros2/urdf/rover_proto_A1/meshes/Lights_Fwd_Link.STL</uri>
            </mesh>
          </geometry>
          <max_contacts>10</max_contacts>
          <surface>
            <contact>
              <ode/>
            </contact>
            <bounce/>
            <friction>
              <torsional>
                <ode/>
              </torsional>
              <ode/>
            </friction>
          </surface>
        </collision>
        <collision name='Chassis_fixed_joint_lump__Lights_Left_Link_collision_7'>
          <pose>0 0 0 0 -0 0</pose>
          <geometry>
            <mesh>
              <scale>1 1 1</scale>
              <uri>model://warehouse_rover_ros2/urdf/rover_proto_A1/meshes/Lights_Left_Link.STL</uri>
            </mesh>
          </geometry>
          <max_contacts>10</max_contacts>
          <surface>
            <contact>
              <ode/>
            </contact>
            <bounce/>
            <friction>
              <torsional>
                <ode/>
              </torsional>
              <ode/>
            </friction>
          </surface>
        </collision>
        <collision name='Chassis_fixed_joint_lump__Lights_Right_Link_collision_8'>
          <pose>0 0 0 0 -0 0</pose>
          <geometry>
            <mesh>
              <scale>1 1 1</scale>
              <uri>model://warehouse_rover_ros2/urdf/rover_proto_A1/meshes/Lights_Right_Link.STL</uri>
            </mesh>
          </geometry>
          <max_contacts>10</max_contacts>
          <surface>
            <contact>
              <ode/>
            </contact>
            <bounce/>
            <friction>
              <torsional>
                <ode/>
              </torsional>
              <ode/>
            </friction>
          </surface>
        </collision>
        <visual name='Chassis_visual'>
          <pose>0 0 0 0 -0 0</pose>
          <geometry>
            <mesh>
              <scale>1 1 1</scale>
              <uri>model://warehouse_rover_ros2/urdf/rover_proto_A1/meshes/Chassis.dae</uri>
            </mesh>
          </geometry>
        </visual>
        <visual name='Chassis_fixed_joint_lump__Camera_Back_Link_visual_1'>
          <pose>-0.50128 0 0.046965 0 -0 0</pose>
          <geometry>
            <mesh>
              <scale>1 1 1</scale>
              <uri>model://warehouse_rover_ros2/urdf/rover_proto_A1/meshes/Camera_Back_Link.dae</uri>
            </mesh>
          </geometry>
        </visual>
        <visual name='Chassis_fixed_joint_lump__Camera_Fwd_Link_visual_2'>
          <pose>0.49872 0 0.046965 0 -0 0</pose>
          <geometry>
            <mesh>
              <scale>1 1 1</scale>
              <uri>model://warehouse_rover_ros2/urdf/rover_proto_A1/meshes/Camera_Fwd_Link.STL</uri>
            </mesh>
          </geometry>
          <material>
            <script>
              <name>Gazebo/Blue</name>
              <uri>file://media/materials/scripts/gazebo.material</uri>
            </script>
          </material>
        </visual>
        <visual name='Chassis_fixed_joint_lump__Lidar_Back_Link_visual_3'>
          <pose>-0.34128 0 0.166 0 -0 1.57</pose>
          <geometry>
            <mesh>
              <scale>1 1 1</scale>
              <uri>model://warehouse_rover_ros2/urdf/rover_proto_A1/meshes/Lidar_Back_Link.STL</uri>
            </mesh>
          </geometry>
          <material>
            <script>
              <name>Gazebo/Red</name>
              <uri>file://media/materials/scripts/gazebo.material</uri>
            </script>
          </material>
        </visual>
        <visual name='Chassis_fixed_joint_lump__Lidar_Fwd_Link_visual_4'>
          <pose>0.33872 0 0.116 0 0 -1.57</pose>
          <geometry>
            <mesh>
              <scale>1 1 1</scale>
              <uri>model://warehouse_rover_ros2/urdf/rover_proto_A1/meshes/Lidar_Fwd_Link.STL</uri>
            </mesh>
          </geometry>
          <material>
            <script>
              <name>Gazebo/Red</name>
              <uri>file://media/materials/scripts/gazebo.material</uri>
            </script>
          </material>
        </visual>
        <visual name='Chassis_fixed_joint_lump__Lights_Back_Link_visual_5'>
          <pose>0 0 0 0 -0 0</pose>
          <geometry>
            <mesh>
              <scale>1 1 1</scale>
              <uri>model://warehouse_rover_ros2/urdf/rover_proto_A1/meshes/Lights_Back_Link.STL</uri>
            </mesh>
          </geometry>
        </visual>
        <visual name='Chassis_fixed_joint_lump__Lights_Fwd_Link_visual_6'>
          <pose>0 0 0 0 -0 0</pose>
          <geometry>
            <mesh>
              <scale>1 1 1</scale>
              <uri>model://warehouse_rover_ros2/urdf/rover_proto_A1/meshes/Lights_Fwd_Link.STL</uri>
            </mesh>
          </geometry>
        </visual>
        <visual name='Chassis_fixed_joint_lump__Lights_Left_Link_visual_7'>
          <pose>0 0 0 0 -0 0</pose>
          <geometry>
            <mesh>
              <scale>1 1 1</scale>
              <uri>model://warehouse_rover_ros2/urdf/rover_proto_A1/meshes/Lights_Left_Link.STL</uri>
            </mesh>
          </geometry>
        </visual>
        <visual name='Chassis_fixed_joint_lump__Lights_Right_Link_visual_8'>
          <pose>0 0 0 0 -0 0</pose>
          <geometry>
            <mesh>
              <scale>1 1 1</scale>
              <uri>model://warehouse_rover_ros2/urdf/rover_proto_A1/meshes/Lights_Right_Link.STL</uri>
            </mesh>
          </geometry>
        </visual>
        <sensor name='camera_scan_back' type='camera'>
          <visualize>1</visualize>
          <update_rate>30</update_rate>
          <camera name='cam_back'>
            <horizontal_fov>1.39626</horizontal_fov>
            <image>
              <width>800</width>
              <height>800</height>
              <format>R8G8B8</format>
            </image>
            <clip>
              <near>0.02</near>
              <far>300</far>
            </clip>
            <noise>
              <type>gaussian</type>
              <mean>0</mean>
              <stddev>0.007</stddev>
            </noise>
          </camera>
          <plugin name='camera_driver_bck' filename='libgazebo_ros_camera.so'>
            <updateRate>0.0</updateRate>
            <cameraName>/camera_back</cameraName>
            <imageTopicName>image_raw</imageTopicName>
            <cameraInfoTopicName>camera_info</cameraInfoTopicName>
            <frameName>Camera_Back_Link_Frame</frameName>
            <hackBaseline>0.07</hackBaseline>
          </plugin>
          <pose>-0.50128 0 0.046965 0 -0 -3.14159</pose>
          <alwaysOn>1</alwaysOn>
        </sensor>
        <sensor name='camera_scan_fwd' type='camera'>
          <visualize>1</visualize>
          <update_rate>30</update_rate>
          <camera name='cam_fwd'>
            <horizontal_fov>1.39626</horizontal_fov>
            <image>
              <width>800</width>
              <height>800</height>
              <format>R8G8B8</format>
            </image>
            <clip>
              <near>0.02</near>
              <far>300</far>
            </clip>
            <noise>
              <type>gaussian</type>
              <mean>0</mean>
              <stddev>0.007</stddev>
            </noise>
          </camera>
          <plugin name='camera_driver_fwd' filename='libgazebo_ros_camera.so'>
            <updateRate>0.0</updateRate>
            <cameraName>/camera_fwd</cameraName>
            <imageTopicName>image_raw</imageTopicName>
            <cameraInfoTopicName>camera_info</cameraInfoTopicName>
            <frameName>Camera_Fwd_Link</frameName>
            <hackBaseline>0.07</hackBaseline>
          </plugin>
          <pose>0.49872 0 0.046965 0 -0 0</pose>
          <alwaysOn>1</alwaysOn>
        </sensor>
        <sensor name='gazebo_lidar_back' type='ray'>
          <visualize>1</visualize>
          <update_rate>12</update_rate>
          <plugin name='gazebo_lidar_back' filename='libgazebo_ros_ray_sensor.so'>
            <ros>
              <remapping>~/out:=lidar_scan_back</remapping>
            </ros>
            <output_type>sensor_msgs/LaserScan</output_type>
            <frame_name>Lidar_Back_Link</frame_name>
          </plugin>
          <ray>
            <scan>
              <horizontal>
                <samples>360</samples>
                <resolution>1</resolution>
                <min_angle>0</min_angle>
                <max_angle>3.14</max_angle>
              </horizontal>
              <vertical>
                <samples>1</samples>
                <min_angle>0</min_angle>
                <max_angle>0</max_angle>
              </vertical>
            </scan>
            <range>
              <min>0.12</min>
              <max>3.5</max>
              <resolution>0.015</resolution>
            </range>
            <noise>
              <type>gaussian</type>
              <mean>0</mean>
              <stddev>0.01</stddev>
            </noise>
          </ray>
          <pose>-0.34128 0 0.166 0 -0 1.57</pose>
        </sensor>
        <sensor name='gazebo_lidar_fwd' type='ray'>
          <visualize>1</visualize>
          <update_rate>12</update_rate>
          <plugin name='gazebo_lidar_fwd' filename='libgazebo_ros_ray_sensor.so'>
            <ros>
              <remapping>~/out:=lidar_scan_fwd</remapping>
            </ros>
            <output_type>sensor_msgs/LaserScan</output_type>
            <frame_name>Lidar_Fwd_Link</frame_name>
          </plugin>
          <ray>
            <scan>
              <horizontal>
                <samples>360</samples>
                <resolution>1</resolution>
                <min_angle>0</min_angle>
                <max_angle>3.14</max_angle>
              </horizontal>
              <vertical>
                <samples>1</samples>
                <min_angle>0</min_angle>
                <max_angle>0</max_angle>
              </vertical>
            </scan>
            <range>
              <min>0.12</min>
              <max>3.5</max>
              <resolution>0.015</resolution>
            </range>
            <noise>
              <type>gaussian</type>
              <mean>0</mean>
              <stddev>0.01</stddev>
            </noise>
          </ray>
          <pose>0.33872 0 0.116 0 0 -1.57</pose>
        </sensor>
        <self_collide>0</self_collide>
        <enable_wind>0</enable_wind>
        <kinematic>0</kinematic>
      </link>
      <joint name='Wheel_1_Joint' type='revolute'>
        <pose relative_to='Chassis'>0.34872 -0.215 -0.04 1.5708 -0 0</pose>
        <parent>Chassis</parent>
        <child>Wheel_1_Link</child>
        <axis>
          <xyz>0 0 -1</xyz>
          <limit>
            <effort>10</effort>
            <velocity>12</velocity>
            <lower>-1e+16</lower>
            <upper>1e+16</upper>
          </limit>
          <dynamics>
            <damping>0.25</damping>
            <friction>0.5</friction>
            <spring_reference>0</spring_reference>
            <spring_stiffness>0</spring_stiffness>
          </dynamics>
        </axis>
      </joint>
      <link name='Wheel_1_Link'>
        <pose relative_to='Wheel_1_Joint'>0 0 0 0 -0 0</pose>
        <inertial>
          <pose>0 -0 -0.016853 0 -0 0</pose>
          <mass>0.456818</mass>
          <inertia>
            <ixx>0.000768197</ixx>
            <ixy>4.1359e-21</ixy>
            <ixz>-4.91914e-19</ixz>
            <iyy>0.000768197</iyy>
            <iyz>2.33003e-19</iyz>
            <izz>0.00134492</izz>
          </inertia>
        </inertial>
        <collision name='Wheel_1_Link_collision'>
          <pose>0 0 0 0 -0 0</pose>
          <geometry>
            <mesh>
              <scale>1 1 1</scale>
              <uri>model://warehouse_rover_ros2/urdf/rover_proto_A1/meshes/Wheel_1_Link.STL</uri>
            </mesh>
          </geometry>
          <max_contacts>10</max_contacts>
          <surface>
            <contact>
              <ode/>
            </contact>
            <bounce/>
            <friction>
              <torsional>
                <ode/>
              </torsional>
              <ode/>
            </friction>
          </surface>
        </collision>
        <visual name='Wheel_1_Link_visual'>
          <pose>0 0 0 0 -0 0</pose>
          <geometry>
            <mesh>
              <scale>1 1 1</scale>
              <uri>model://warehouse_rover_ros2/urdf/rover_proto_A1/meshes/Wheel_1_Link.STL</uri>
            </mesh>
          </geometry>
        </visual>
        <self_collide>0</self_collide>
        <enable_wind>0</enable_wind>
        <kinematic>0</kinematic>
      </link>
      <joint name='Wheel_2_Joint' type='revolute'>
        <pose relative_to='Chassis'>0.34872 0.215 -0.04 1.5708 -0 0</pose>
        <parent>Chassis</parent>
        <child>Wheel_2_Link</child>
        <axis>
          <xyz>0 0 -1</xyz>
          <limit>
            <effort>10</effort>
            <velocity>12</velocity>
            <lower>-1e+16</lower>
            <upper>1e+16</upper>
          </limit>
          <dynamics>
            <damping>0.25</damping>
            <friction>0.5</friction>
            <spring_reference>0</spring_reference>
            <spring_stiffness>0</spring_stiffness>
          </dynamics>
        </axis>
      </joint>
      <link name='Wheel_2_Link'>
        <pose relative_to='Wheel_2_Joint'>0 0 0 0 -0 0</pose>
        <inertial>
          <pose>-0 0 0.016853 0 -0 0</pose>
          <mass>0.456818</mass>
          <inertia>
            <ixx>0.000768197</ixx>
            <ixy>1.02115e-18</ixy>
            <ixz>-7.60711e-19</ixz>
            <iyy>0.000768197</iyy>
            <iyz>3.64043e-19</iyz>
            <izz>0.00134492</izz>
          </inertia>
        </inertial>
        <collision name='Wheel_2_Link_collision'>
          <pose>0 0 0 0 -0 0</pose>
          <geometry>
            <mesh>
              <scale>1 1 1</scale>
              <uri>model://warehouse_rover_ros2/urdf/rover_proto_A1/meshes/Wheel_2_Link.STL</uri>
            </mesh>
          </geometry>
          <max_contacts>10</max_contacts>
          <surface>
            <contact>
              <ode/>
            </contact>
            <bounce/>
            <friction>
              <torsional>
                <ode/>
              </torsional>
              <ode/>
            </friction>
          </surface>
        </collision>
        <visual name='Wheel_2_Link_visual'>
          <pose>0 0 0 0 -0 0</pose>
          <geometry>
            <mesh>
              <scale>1 1 1</scale>
              <uri>model://warehouse_rover_ros2/urdf/rover_proto_A1/meshes/Wheel_2_Link.STL</uri>
            </mesh>
          </geometry>
        </visual>
        <self_collide>0</self_collide>
        <enable_wind>0</enable_wind>
        <kinematic>0</kinematic>
      </link>
      <joint name='Wheel_3_Joint' type='revolute'>
        <pose relative_to='Chassis'>-0.35128 0.21499 -0.04 1.5708 -0 0</pose>
        <parent>Chassis</parent>
        <child>Wheel_3_Link</child>
        <axis>
          <xyz>0 0 -1</xyz>
          <limit>
            <effort>10</effort>
            <velocity>12</velocity>
            <lower>-1e+16</lower>
            <upper>1e+16</upper>
          </limit>
          <dynamics>
            <damping>0.25</damping>
            <friction>0.5</friction>
            <spring_reference>0</spring_reference>
            <spring_stiffness>0</spring_stiffness>
          </dynamics>
        </axis>
      </joint>
      <link name='Wheel_3_Link'>
        <pose relative_to='Wheel_3_Joint'>0 0 0 0 -0 0</pose>
        <inertial>
          <pose>-0 -0 0.016853 0 -0 0</pose>
          <mass>0.456818</mass>
          <inertia>
            <ixx>0.000768197</ixx>
            <ixy>-1.88597e-19</ixy>
            <ixz>-4.93382e-19</ixz>
            <iyy>0.000768197</iyy>
            <iyz>-2.11063e-19</iyz>
            <izz>0.00134492</izz>
          </inertia>
        </inertial>
        <collision name='Wheel_3_Link_collision'>
          <pose>0 0 0 0 -0 0</pose>
          <geometry>
            <mesh>
              <scale>1 1 1</scale>
              <uri>model://warehouse_rover_ros2/urdf/rover_proto_A1/meshes/Wheel_3_Link.STL</uri>
            </mesh>
          </geometry>
          <max_contacts>10</max_contacts>
          <surface>
            <contact>
              <ode/>
            </contact>
            <bounce/>
            <friction>
              <torsional>
                <ode/>
              </torsional>
              <ode/>
            </friction>
          </surface>
        </collision>
        <visual name='Wheel_3_Link_visual'>
          <pose>0 0 0 0 -0 0</pose>
          <geometry>
            <mesh>
              <scale>1 1 1</scale>
              <uri>model://warehouse_rover_ros2/urdf/rover_proto_A1/meshes/Wheel_3_Link.STL</uri>
            </mesh>
          </geometry>
        </visual>
        <self_collide>0</self_collide>
        <enable_wind>0</enable_wind>
        <kinematic>0</kinematic>
      </link>
      <joint name='Wheel_4_Joint' type='revolute'>
        <pose relative_to='Chassis'>-0.35128 -0.215 -0.04 1.5708 -0 0</pose>
        <parent>Chassis</parent>
        <child>Wheel_4_Link</child>
        <axis>
          <xyz>0 0 -1</xyz>
          <limit>
            <effort>10</effort>
            <velocity>12</velocity>
            <lower>-1e+16</lower>
            <upper>1e+16</upper>
          </limit>
          <dynamics>
            <damping>0.25</damping>
            <friction>0.5</friction>
            <spring_reference>0</spring_reference>
            <spring_stiffness>0</spring_stiffness>
          </dynamics>
        </axis>
      </joint>
      <link name='Wheel_4_Link'>
        <pose relative_to='Wheel_4_Joint'>0 0 0 0 -0 0</pose>
        <inertial>
          <pose>0 0 -0.016853 0 -0 0</pose>
          <mass>0.456818</mass>
          <inertia>
            <ixx>0.000768197</ixx>
            <ixy>-7.84271e-19</ixy>
            <ixz>-6.61935e-19</ixz>
            <iyy>0.000768197</iyy>
            <iyz>-2.6149e-19</iyz>
            <izz>0.00134492</izz>
          </inertia>
        </inertial>
        <collision name='Wheel_4_Link_collision'>
          <pose>0 0 0 0 -0 0</pose>
          <geometry>
            <mesh>
              <scale>1 1 1</scale>
              <uri>model://warehouse_rover_ros2/urdf/rover_proto_A1/meshes/Wheel_4_Link.STL</uri>
            </mesh>
          </geometry>
          <max_contacts>10</max_contacts>
          <surface>
            <contact>
              <ode/>
            </contact>
            <bounce/>
            <friction>
              <torsional>
                <ode/>
              </torsional>
              <ode/>
            </friction>
          </surface>
        </collision>
        <visual name='Wheel_4_Link_visual'>
          <pose>0 0 0 0 -0 0</pose>
          <geometry>
            <mesh>
              <scale>1 1 1</scale>
              <uri>model://warehouse_rover_ros2/urdf/rover_proto_A1/meshes/Wheel_4_Link.STL</uri>
            </mesh>
          </geometry>
        </visual>
        <self_collide>0</self_collide>
        <enable_wind>0</enable_wind>
        <kinematic>0</kinematic>
      </link>
      <static>0</static>
      <plugin name='diff_drive_fwd' filename='libgazebo_ros_diff_drive.so'>
        <left_joint>Wheel_2_Joint</left_joint>
        <right_joint>Wheel_1_Joint</right_joint>
        <wheel_separation>0.43</wheel_separation>
        <wheel_diameter>0.16</wheel_diameter>
        <max_wheel_torque>30</max_wheel_torque>
        <max_wheel_acceleration>1.50</max_wheel_acceleration>
        <publish_odom>1</publish_odom>
        <publish_odom_tf>1</publish_odom_tf>
        <publish_wheel_tf>1</publish_wheel_tf>
        <odometry_frame>base_footprint</odometry_frame>
        <robot_base_frame>Chassis</robot_base_frame>
      </plugin>
      <plugin name='diff_drive_back' filename='libgazebo_ros_diff_drive.so'>
        <left_joint>Wheel_3_Joint</left_joint>
        <right_joint>Wheel_4_Joint</right_joint>
        <wheel_separation>0.43</wheel_separation>
        <wheel_diameter>0.16</wheel_diameter>
        <max_wheel_torque>30</max_wheel_torque>
        <max_wheel_acceleration>1.50</max_wheel_acceleration>
        <publish_odom>1</publish_odom>
        <publish_odom_tf>1</publish_odom_tf>
        <publish_wheel_tf>1</publish_wheel_tf>
        <odometry_frame>base_footprint</odometry_frame>
        <robot_base_frame>Chassis</robot_base_frame>
      </plugin>
      <pose>0 0 0 0 -0 0</pose>
    </model>
    <light name='user_directional_light_0' type='directional'>
      <pose>3.28777 -7.89594 1 0 -0 0</pose>
      <diffuse>0.5 0.5 0.5 1</diffuse>
      <specular>0.1 0.1 0.1 1</specular>
      <direction>0.1 0.1 -0.9</direction>
      <attenuation>
        <range>20</range>
        <constant>0.5</constant>
        <linear>0.01</linear>
        <quadratic>0.001</quadratic>
      </attenuation>
      <cast_shadows>1</cast_shadows>
      <spot>
        <inner_angle>0</inner_angle>
        <outer_angle>0</outer_angle>
        <falloff>0</falloff>
      </spot>
    </light>
    <light name='user_directional_light_1' type='directional'>
      <pose>-2.70099 1.56133 1 0 -0 0</pose>
      <diffuse>0.5 0.5 0.5 1</diffuse>
      <specular>0.1 0.1 0.1 1</specular>
      <direction>0.1 0.1 -0.9</direction>
      <attenuation>
        <range>20</range>
        <constant>0.5</constant>
        <linear>0.01</linear>
        <quadratic>0.001</quadratic>
      </attenuation>
      <cast_shadows>1</cast_shadows>
      <spot>
        <inner_angle>0</inner_angle>
        <outer_angle>0</outer_angle>
        <falloff>0</falloff>
      </spot>
    </light>
    <light name='user_directional_light_2' type='directional'>
      <pose>5.65592 4.53366 1 0 -0 0</pose>
      <diffuse>0.5 0.5 0.5 1</diffuse>
      <specular>0.1 0.1 0.1 1</specular>
      <direction>0.1 0.1 -0.9</direction>
      <attenuation>
        <range>20</range>
        <constant>0.5</constant>
        <linear>0.01</linear>
        <quadratic>0.001</quadratic>
      </attenuation>
      <cast_shadows>1</cast_shadows>
      <spot>
        <inner_angle>0</inner_angle>
        <outer_angle>0</outer_angle>
        <falloff>0</falloff>
      </spot>
    </light>
    <light name='user_directional_light_3' type='directional'>
      <pose>7.02737 -2.79913 1 0 -0 0</pose>
      <diffuse>0.5 0.5 0.5 1</diffuse>
      <specular>0.1 0.1 0.1 1</specular>
      <direction>0.1 0.1 -0.9</direction>
      <attenuation>
        <range>20</range>
        <constant>0.5</constant>
        <linear>0.01</linear>
        <quadratic>0.001</quadratic>
      </attenuation>
      <cast_shadows>1</cast_shadows>
      <spot>
        <inner_angle>0</inner_angle>
        <outer_angle>0</outer_angle>
        <falloff>0</falloff>
      </spot>
    </light>
    <light name='user_directional_light_4' type='directional'>
      <pose>-2.73559 -5.19311 1 0 -0 0</pose>
      <diffuse>0.5 0.5 0.5 1</diffuse>
      <specular>0.1 0.1 0.1 1</specular>
      <direction>0.1 0.1 -0.9</direction>
      <attenuation>
        <range>20</range>
        <constant>0.5</constant>
        <linear>0.01</linear>
        <quadratic>0.001</quadratic>
      </attenuation>
      <cast_shadows>1</cast_shadows>
      <spot>
        <inner_angle>0</inner_angle>
        <outer_angle>0</outer_angle>
        <falloff>0</falloff>
      </spot>
    </light>
    <light name='user_directional_light_5' type='directional'>
      <pose>10.6409 -2.37644 1 0 -0 0</pose>
      <diffuse>0.5 0.5 0.5 1</diffuse>
      <specular>0.1 0.1 0.1 1</specular>
      <direction>0.1 0.1 -0.9</direction>
      <attenuation>
        <range>20</range>
        <constant>0.5</constant>
        <linear>0.01</linear>
        <quadratic>0.001</quadratic>
      </attenuation>
      <cast_shadows>1</cast_shadows>
      <spot>
        <inner_angle>0</inner_angle>
        <outer_angle>0</outer_angle>
        <falloff>0</falloff>
      </spot>
    </light>
  </world>
</sdf>
